#VRML_SIM R2022a utf8
WorldInfo {
  contactProperties [
    ContactProperties {
      material1 "load"
      material2 "floor"
      coulombFriction [
        0.1
      ]
    }
  ]
}
Viewpoint {
  orientation 0.03609547415588842 -0.995153665214478 0.09146747703775587 5.884304365754602
  position -0.8304682345412 0.004817308172057374 0.32650879448154496
}
TexturedBackground {
}
TexturedBackgroundLight {
}
DEF FLOOR Solid {
  children [
    DEF LINE_SHAPE Shape {
      appearance PBRAppearance {
        baseColorMap ImageTexture {
          url [
            "https://raw.githubusercontent.com/cyberbotics/webots/R2022a/projects/default/worlds/textures/texture_grid.png"
          ]
        }
        roughness 0.5
        metalness 0
      }
      geometry IndexedFaceSet {
        coord Coordinate {
          point [
            10 10 0
            -10 10 0
            -10 -10 0
            10 -10 0
          ]
        }
        texCoord TextureCoordinate {
          point [
            0 10
            0 0
            10 0
            10 10
          ]
        }
        coordIndex [
          0, 1, 2, 3, -1
        ]
        texCoordIndex [
          0, 1, 2, 3, -1
        ]
      }
    }
    Transform {
      children [
        Shape {
          appearance PBRAppearance {
            baseColor 0.647059 0.164706 0.164706
            roughness 1
            metalness 0
          }
          geometry Box {
            size 0.5 0.5 0.001
          }
        }
      ]
    }
  ]
  name "ground"
  contactMaterial "floor"
  boundingObject Transform {
    translation 0 0 -1
    children [
      Box {
        size 20 20 2
      }
    ]
  }
  locked TRUE
}
DEF GA Robot {
  children [
    Emitter {
      channel 1
    }
    Display {
      width 200
      height 100
    }
  ]
  controller "advanced_genetic_algorithm_supervisor"
  supervisor TRUE
}
DEF DOG Robot {
  translation -0.183843 -0.00904631 0.0799631
  rotation 0.00046313178180094254 0.9999998927544705 -3.138776743685617e-09 6.1798758910936e-05
  children [
    Receiver {
      children [
        Solid {
          translation 0 0.05 0.02
          children [
            Shape {
              appearance PBRAppearance {
                baseColor 1 0 0
              }
              geometry Cylinder {
                height 0.005
                radius 0.005
              }
            }
          ]
        }
      ]
      channel 1
    }
    HingeJoint {
      jointParameters HingeJointParameters {
        position 5.360640585466814e-08
        anchor 0.035 -0.08 0
        minStop -0.7
        maxStop 0.7
      }
      device [
        PositionSensor {
          name "pos_leg_1"
        }
        RotationalMotor {
          name "leg_1"
        }
      ]
      endPoint Solid {
        translation 0.035 -0.08000000000000024 9.518089315913942e-09
        rotation 2.682455463580859e-08 0.9999999999999994 2.6803202868432133e-08 1.5699999999999814
        children [
          DEF Joint Shape {
            appearance PBRAppearance {
            }
            geometry Box {
              size 0.02 0.02 0.02
            }
          }
          Solid {
            translation 0.02 0 0
            children [
              Solid {
                translation 0.02 0 0
                children [
                  Solid {
                    translation 0.02 0 0
                    children [
                      DEF Leg Shape {
                        appearance PBRAppearance {
                          roughness 1
                          metalness 0
                        }
                        geometry Box {
                          size 0.02 0.02 0.02
                        }
                      }
                    ]
                    boundingObject USE Leg
                    physics Physics {
                    }
                  }
                  DEF Leg Shape {
                    appearance PBRAppearance {
                    }
                    geometry Box {
                      size 0.02 0.02 0.02
                    }
                  }
                ]
                boundingObject USE Leg
                physics Physics {
                }
              }
              DEF Leg Shape {
                appearance PBRAppearance {
                }
                geometry Box {
                  size 0.02 0.02 0.02
                }
              }
            ]
            boundingObject USE Leg
            physics Physics {
            }
          }
        ]
        name "solid(4)"
        boundingObject USE Joint
        physics DEF Physics_Wheel Physics {
        }
      }
    }
    HingeJoint {
      jointParameters HingeJointParameters {
        position 5.359832349332421e-08
        anchor -0.035 -0.08 0
        minStop -0.7
        maxStop 0.7
      }
      device [
        PositionSensor {
          name "pos_leg_2"
        }
        RotationalMotor {
          name "leg_2"
        }
      ]
      endPoint Solid {
        translation -0.035 -0.08 0
        rotation -2.9472124464758067e-09 1 -2.9448675284672674e-09 1.5699999999999792
        children [
          DEF Joint Shape {
            appearance PBRAppearance {
            }
            geometry Box {
              size 0.02 0.02 0.02
            }
          }
          Solid {
            translation 0.02 0 0
            children [
              Solid {
                translation 0.02 0 0
                children [
                  Solid {
                    translation 0.02 0 0
                    children [
                      DEF Leg Shape {
                        appearance PBRAppearance {
                          roughness 1
                          metalness 0
                        }
                        geometry Box {
                          size 0.02 0.02 0.02
                        }
                      }
                    ]
                    boundingObject USE Leg
                    physics Physics {
                    }
                  }
                  DEF Leg Shape {
                    appearance PBRAppearance {
                    }
                    geometry Box {
                      size 0.02 0.02 0.02
                    }
                  }
                ]
                boundingObject USE Leg
                physics Physics {
                }
              }
              DEF Leg Shape {
                appearance PBRAppearance {
                }
                geometry Box {
                  size 0.02 0.02 0.02
                }
              }
            ]
            boundingObject USE Leg
            physics Physics {
            }
          }
        ]
        name "solid(1)"
        boundingObject USE Joint
        physics DEF Physics_Wheel Physics {
        }
      }
    }
    HingeJoint {
      jointParameters HingeJointParameters {
        position 5.359807136404144e-08
        anchor -0.035 0.08 0
        minStop -0.7
        maxStop 0.7
      }
      device [
        PositionSensor {
          name "pos_leg_3"
        }
        RotationalMotor {
          name "leg_3"
        }
      ]
      endPoint Solid {
        translation -0.035 0.08 0
        rotation 2.6820385445062383e-08 0.9999999999999994 2.6799035721288658e-08 1.5699999999999807
        children [
          DEF Joint Shape {
            appearance PBRAppearance {
            }
            geometry Box {
              size 0.02 0.02 0.02
            }
          }
          Solid {
            translation 0.02 0 0
            children [
              Solid {
                translation 0.02 0 0
                children [
                  Solid {
                    translation 0.02 0 0
                    children [
                      DEF Leg Shape {
                        appearance PBRAppearance {
                          roughness 1
                          metalness 0
                        }
                        geometry Box {
                          size 0.02 0.02 0.02
                        }
                      }
                    ]
                    boundingObject USE Leg
                    physics Physics {
                    }
                  }
                  DEF Leg Shape {
                    appearance PBRAppearance {
                    }
                    geometry Box {
                      size 0.02 0.02 0.02
                    }
                  }
                ]
                boundingObject USE Leg
                physics Physics {
                }
              }
              DEF Leg Shape {
                appearance PBRAppearance {
                }
                geometry Box {
                  size 0.02 0.02 0.02
                }
              }
            ]
            boundingObject USE Leg
            physics Physics {
            }
          }
        ]
        name "solid(2)"
        boundingObject USE Joint
        physics DEF Physics_Wheel Physics {
        }
      }
    }
    HingeJoint {
      jointParameters HingeJointParameters {
        position 5.360641983938869e-08
        anchor 0.035 0.08 0
        minStop -0.7
        maxStop 0.7
      }
      device [
        PositionSensor {
          name "pos_leg_4"
        }
        RotationalMotor {
          name "leg_4"
        }
      ]
      endPoint Solid {
        translation 0.035 0.08 0
        rotation 2.6824561712275084e-08 0.9999999999999994 2.6803209723354585e-08 1.569999999999985
        children [
          DEF Joint Shape {
            appearance PBRAppearance {
            }
            geometry Box {
              size 0.02 0.02 0.02
            }
          }
          Solid {
            translation 0.02 0 0
            children [
              Solid {
                translation 0.02 0 0
                children [
                  Solid {
                    translation 0.02 0 0
                    children [
                      DEF Leg Shape {
                        appearance PBRAppearance {
                          roughness 1
                          metalness 0
                        }
                        geometry Box {
                          size 0.02 0.02 0.02
                        }
                      }
                    ]
                    boundingObject USE Leg
                    physics Physics {
                    }
                  }
                  DEF Leg Shape {
                    appearance PBRAppearance {
                    }
                    geometry Box {
                      size 0.02 0.02 0.02
                    }
                  }
                ]
                boundingObject USE Leg
                physics Physics {
                }
              }
              DEF Leg Shape {
                appearance PBRAppearance {
                }
                geometry Box {
                  size 0.02 0.02 0.02
                }
              }
            ]
            boundingObject USE Leg
            physics Physics {
            }
          }
        ]
        name "solid(3)"
        boundingObject USE Joint
        physics DEF Physics_Wheel Physics {
        }
      }
    }
    DEF Body Shape {
      appearance PBRAppearance {
        baseColor 1 1 0.1
        roughness 1
        metalness 0
      }
      geometry Box {
        size 0.05 0.2 0.03
      }
    }
  ]
  name "dog"
  boundingObject USE Body
  physics Physics {
  }
  controller "advanced_genetic_algorithm_dog"
  supervisor TRUE
}
