#VRML_SIM R2022a utf8
WorldInfo {
  contactProperties [
    ContactProperties {
      material1 "load"
      material2 "floor"
      coulombFriction [
        0.1
      ]
    }
  ]
}
Viewpoint {
  orientation 0.08913647284764363 -0.9799488345252401 -0.17819924500655174 5.7588020935515605
  position -1.551547747136234 0.02729392004709874 0.8812189973068788
}
TexturedBackground {
}
TexturedBackgroundLight {
}
DEF FLOOR Solid {
  children [
    DEF LINE_SHAPE Shape {
      appearance PBRAppearance {
        baseColorMap ImageTexture {
          url [
            "https://raw.githubusercontent.com/cyberbotics/webots/R2022a/projects/default/worlds/textures/texture_grid.png"
          ]
        }
        roughness 0.5
        metalness 0
      }
      geometry IndexedFaceSet {
        coord Coordinate {
          point [
            10 10 0
            -10 10 0
            -10 -10 0
            10 -10 0
          ]
        }
        texCoord TextureCoordinate {
          point [
            0 10
            0 0
            10 0
            10 10
          ]
        }
        coordIndex [
          0, 1, 2, 3, -1
        ]
        texCoordIndex [
          0, 1, 2, 3, -1
        ]
      }
    }
    Transform {
      children [
        Shape {
          appearance PBRAppearance {
            baseColor 0.647059 0.164706 0.164706
            roughness 1
            metalness 0
          }
          geometry Box {
            size 0.5 0.5 0.001
          }
        }
      ]
    }
  ]
  name "ground"
  contactMaterial "floor"
  boundingObject Transform {
    translation 0 0 -1
    children [
      Box {
        size 20 20 2
      }
    ]
  }
  locked TRUE
}
DEF OBSTACLE Solid {
  translation 1 0 0.03
  children [
    DEF BOX_SHAPE Shape {
      appearance PBRAppearance {
        baseColor 1 0.647059 0
        roughness 1
        metalness 0
      }
      geometry Cylinder {
        height 0.05
        radius 0.1
      }
    }
  ]
  name "obstacle"
  boundingObject USE BOX_SHAPE
}
DEF LOAD Solid {
  translation 0.03691271336421083 -6.077470159012052e-08 0.024918650076873532
  rotation 0.07229470949057412 -0.9973047231076834 0.012520552974226011 2.6129844533227744e-05
  children [
    DEF BOX_SHAPE Shape {
      appearance PBRAppearance {
        baseColor 0.627451 0.12549 0.941176
        roughness 1
        metalness 0
      }
      geometry Cylinder {
        height 0.05
        radius 0.05
      }
    }
  ]
  contactMaterial "load"
  boundingObject USE BOX_SHAPE
  physics Physics {
  }
}
DEF ROBOT E-puck {
  translation -0.050005903274872934 0.0013985120623303455 -6.258139266428903e-05
  rotation -0.05500556771960843 -0.9409078212494085 0.3341659160230656 0.0017321894095764906
  controller "advanced_genetic_algorithm"
}
DEF GA Robot {
  children [
    Emitter {
      channel 1
    }
    Display {
      width 200
      height 100
    }
  ]
  controller "advanced_genetic_algorithm_supervisor"
  supervisor TRUE
}
DEF DOG Robot {
  translation -0.18384799939944835 -0.009046309987933134 0.029963116980971795
  rotation 0.00046313178180094254 0.9999998927544705 -3.138776743685617e-09 6.1798758910936e-05
  children [
    Receiver {
      children [
        Solid {
          translation 0 0.05 0.02
          children [
            Shape {
              appearance PBRAppearance {
                baseColor 1 0 0
              }
              geometry Cylinder {
                height 0.005
                radius 0.005
              }
            }
          ]
        }
      ]
    }
    HingeJoint {
      jointParameters HingeJointParameters {
        position 5.360640585466814e-08
        anchor 0.035 -0.08 0
        minStop -0.7
        maxStop 0.7
      }
      device [
        PositionSensor {
          name "pos_leg_1"
        }
        RotationalMotor {
          name "leg_1"
        }
      ]
      endPoint Solid {
        translation 0.035 -0.08000000000000024 9.518089305673619e-09
        rotation 2.6824555588055867e-08 0.9999999999999994 2.6803202946968032e-08 1.57
        children [
          DEF Joint Shape {
            appearance PBRAppearance {
            }
            geometry Box {
              size 0.02 0.02 0.02
            }
          }
          Solid {
            translation 0.02 0 0
            children [
              DEF Leg Shape {
                appearance PBRAppearance {
                }
                geometry Box {
                  size 0.02 0.02 0.02
                }
              }
            ]
            boundingObject USE Leg
            physics Physics {
            }
          }
        ]
        name "solid(4)"
        boundingObject USE Joint
        physics DEF Physics_Wheel Physics {
        }
      }
    }
    GPS {
      children [
        Solid {
          translation 0 0 0.02
          children [
            Shape {
              appearance PBRAppearance {
              }
              geometry Cylinder {
                height 0.005
                radius 0.005
              }
            }
          ]
        }
      ]
    }
    HingeJoint {
      jointParameters HingeJointParameters {
        position 5.359832349332421e-08
        anchor -0.035 -0.08 0
        minStop -0.7
        maxStop 0.7
      }
      device [
        PositionSensor {
          name "pos_leg_2"
        }
        RotationalMotor {
          name "leg_2"
        }
      ]
      endPoint Solid {
        translation -0.035 -0.08 0
        rotation -2.947213447808747e-09 1 -2.9448673419442253e-09 1.5699999999999985
        children [
          DEF Joint Shape {
            appearance PBRAppearance {
            }
            geometry Box {
              size 0.02 0.02 0.02
            }
          }
          Solid {
            translation 0.02 0 0
            children [
              DEF Leg Shape {
                appearance PBRAppearance {
                }
                geometry Box {
                  size 0.02 0.02 0.02
                }
              }
            ]
            boundingObject USE Leg
            physics Physics {
            }
          }
        ]
        name "solid(1)"
        boundingObject USE Joint
        physics DEF Physics_Wheel Physics {
        }
      }
    }
    HingeJoint {
      jointParameters HingeJointParameters {
        position 5.359807136404144e-08
        anchor -0.035 0.08 0
        minStop -0.7
        maxStop 0.7
      }
      device [
        PositionSensor {
          name "pos_leg_3"
        }
        RotationalMotor {
          name "leg_3"
        }
      ]
      endPoint Solid {
        translation -0.035 0.08 0
        rotation 2.6820384777506793e-08 0.9999999999999994 2.6799035740922637e-08 1.5699999999999974
        children [
          DEF Joint Shape {
            appearance PBRAppearance {
            }
            geometry Box {
              size 0.02 0.02 0.02
            }
          }
          Solid {
            translation 0.02 0 0
            children [
              DEF Leg Shape {
                appearance PBRAppearance {
                }
                geometry Box {
                  size 0.02 0.02 0.02
                }
              }
            ]
            boundingObject USE Leg
            physics Physics {
            }
          }
        ]
        name "solid(2)"
        boundingObject USE Joint
        physics DEF Physics_Wheel Physics {
        }
      }
    }
    HingeJoint {
      jointParameters HingeJointParameters {
        position 5.360641983938869e-08
        anchor 0.035 0.08 0
        minStop -0.7
        maxStop 0.7
      }
      device [
        PositionSensor {
          name "pos_leg_4"
        }
        RotationalMotor {
          name "leg_4"
        }
      ]
      endPoint Solid {
        translation 0.035 0.08 0
        rotation 2.682456253690164e-08 0.9999999999999994 2.680320993932831e-08 1.5699999999999994
        children [
          DEF Joint Shape {
            appearance PBRAppearance {
            }
            geometry Box {
              size 0.02 0.02 0.02
            }
          }
          Solid {
            translation 0.02 0 0
            children [
              DEF Leg Shape {
                appearance PBRAppearance {
                }
                geometry Box {
                  size 0.02 0.02 0.02
                }
              }
            ]
            boundingObject USE Leg
            physics Physics {
            }
          }
        ]
        name "solid(3)"
        boundingObject USE Joint
        physics DEF Physics_Wheel Physics {
        }
      }
    }
    DEF Body Shape {
      appearance PBRAppearance {
        baseColor 1 1 0.1
        roughness 1
        metalness 0
      }
      geometry Box {
        size 0.05 0.2 0.03
      }
    }
  ]
  name "dog"
  boundingObject USE Body
  physics Physics {
  }
  controller "advanced_genetic_algorithm_dog"
  supervisor TRUE
}
